Workbook

Sheet meta data
A2: Data are collected annually through the School census exercise.
A3: This takes place in early October, when each school is required to submit a return detailing information about the numbers of pupils on their register.
A4: In 2023/24, the school census date was 6th October. Figures in these tables are a snapshot of the situation in schools at that time.
A5: Among the information collected are details on: year group, gender, age, religion, ethnicity, Special Educational Needs and free school meal entitlement.
A6: Statistics produced from the school census exercise qualify as National Statistics.
A8: Data in this spreadsheet has been impacted by industrial action, due to ongoing Action Short of Strike (ASOS).
A9: Although data has been received from all schools, for 25% of schools (primary, post primary and special schools) pupil level information has not been received in electronic format.
A10: For those schools refusing to submit electronically, a paper return was received. The result of this is that the Department has either been unable to obtain all the information usually
A11: received via electronic census returns, for example religion and sex, and it has not been possible to fully undertake normal validation processes. Some validations have been
A12: impossible due to a lack of pupil level information. Further information can be found in the notes section of our bulletin (https://www.education-ni.gov.uk/publications/annual-enrolments-schools-and-funded-pre-school-education-northern-ireland-202324)
A14: Specialist Provision
A15: Specialist Provisions (previously known as ‘Learning Support Centres’) refers to classes/units in mainstream primary and post primary schools that have been approved by the Education Authority
... A35: Key
A36: * | B36: refers to less than five cases where data is considered sensitive.
A37: # | B37: means figure has been supressed under rules of disclosure.
A39: Enquiries relating to information collected in the school census in Northern Ireland
A40: should be addressed to:
A42: Statistics and Research Team
A43: Department of Education,
A44: Rathgael House,
A45: Balloo Road,
A46: Bangor,
A47: Co. Down
A48: BT19 7PR.
A50: Telephone: 028 9127 9707
A52: email: | B52: census@education-ni.gov.uk

Sheet reference data
A1: Data on Pupils attending primary schools in Northern Ireland 2023/24: reference data
A4: De ref | B4: school name | C4: address 1 | D4: town | E4: postcode | F4: school type | G4: management type | H4: constituency | I4: district council (2014) | J4: ward (2014) | K4: DEA (2014) | L4: Urban/ Rural | M4: Irish Medium School
A5: 1010012 | B5: Belmont Primary School, Belfast | C5: Belmont Road | D5: Belfast | E5: BT4 2AG | F5: Primary | G5: Controlled | H5: Belfast East | I5: Belfast | J5: Knock | K5: Ormiston | L5: URBAN | M5: No
A6: 1010063 | B6: Currie Primary School, Belfast | C6: 111-113 Limestone Road | D6: Belfast | E6: BT15 3AB | F6: Primary | G6: Controlled | H6: Belfast North | I6: Belfast | J6: Duncairn | K6: Castle | L6: URBAN | M6: No
A7: 1010146 | B7: Euston Street Primary School, Belfast | C7: Euston Street | D7: Belfast | E7: BT6 9AG | F7: Primary | G7: Controlled | H7: Belfast East | I7: Belfast | J7: Beersbridge | K7: Titanic | L7: URBAN | M7: No
A8: 1010157 | B8: Rosetta Primary School | C8: 21-23 Knockbreda Road | D8: Belfast | E8: BT6 0JA | F8: Primary | G8: Controlled | H8: Belfast South | I8: Belfast | J8: Rosetta | K8: Lisnasharragh | L8: URBAN | M8: No
A9: 1010205 | B9: Forth River Primary School, Belfast | C9: Cairnmartin Road | D9: Belfast | E9: BT13 3PQ | F9: Primary | G9: Controlled | H9: Belfast West | I9: Belfast | J9: Forth River | K9: Court | L9: URBAN | M9: No
A10: 1010221 | B10: Springfield Primary School, Belfast | C10: Springfield Road | D10: Belfast | E10: BT12 7DJ | F10: Primary | G10: Controlled | H10: Belfast West | I10: Belfast | J10: Ballygomartin | K10: Court | L10: URBAN | M10: No
A11: 1010252 | B11: Strandtown Primary School, Belfast | C11: North Road | D11: Belfast | E11: BT4 3DJ | F11: Primary | G11: Controlled | H11: Belfast East | I11: Belfast | J11: Knock | K11: Ormiston | L11: URBAN | M11: No
A12: 1010255 | B12: Elmgrove Primary School, Belfast | C12: Beersbridge Road | D12: Belfast | E12: BT5 4RS | F12: Primary | G12: Controlled | H12: Belfast East | I12: Belfast | J12: Beersbridge | K12: Titanic | L12: URBAN | M12: No
A13: 1010266 | B13: Seaview Primary School, Belfast | C13: Seaview Drive | D13: Belfast | E13: BT15 3NB | F13: Primary | G13: Controlled | H13: Belfast North | I13: Belfast | J13: Fortwilliam | K13: Castle | L13: URBAN | M13: No
A14: 1010267 | B14: Nettlefield Primary School, Belfast | C14: Radnor Street | D14: Belfast | E14: BT6 8BG | F14: Primary | G14: Controlled | H14: Belfast South | I14: Belfast | J14: Woodstock | K14: Titanic | L14: URBAN | M14: No
A15: 1010273 | B15: Orangefield Primary School, Belfast | C15: Cameronian Drive | D15: Belfast | E15: BT5 6BA | F15: Primary | G15: Controlled | H15: Belfast East | I15: Belfast | J15: Orangefield | K15: Lisnasharragh | L15: URBAN | M15: No
A16: 1010282 | B16: Carr's Glen Primary School, Belfast | C16: Oldpark Road | D16: Belfast | E16: BT14 6QX | F16: Primary | G16: Controlled | H16: Belfast North | I16: Belfast | J16: Ballysillan | K16: Oldpark | L16: URBAN | M16: No
... A791: 5620263 | B791: Armagh Royal Preparatory Department | C791: College Hill | D791: Armagh | E791: BT61 9DG | F791: Prep Department | G791: Voluntary | H791: Newry And Armagh | I791: Armagh City, Banbridge and Craigavon | J791: The Mall | K791: Armagh | L791: URBAN | M791: No

Sheet Enrolments
A1: Data on Pupils1,2 attending primary schools in Northern Ireland 2023/24: enrolment data
C3: Total enrolment
A4: DE ref | B4: school name | C4: nursery full-time | D4: nursery part-time | E4: reception pupils | F4: year 1 | G4: year 2 | H4: year 3 | I4: year 4 | J4: year 5 | K4: year 6 | L4: year 7 | M4: total enrolment
A5: 1010012 | B5: Belmont Primary School, Belfast | C5: 0 | D5: 0 | E5: 0 | F5: 83 | G5: 80 | H5: 82 | I5: 0 | J5: 0 | K5: 0 | L5: 0 | M5: 245
A6: 1010063 | B6: Currie Primary School, Belfast | C6: 0 | D6: 21 | E6: 0 | F6: 24 | G6: 19 | H6: 25 | I6: 28 | J6: 29 | K6: 22 | L6: 24 | M6: 192
A7: 1010146 | B7: Euston Street Primary School, Belfast | C7: 52 | D7: 0 | E7: 0 | F7: 41 | G7: 48 | H7: 51 | I7: 43 | J7: 42 | K7: 45 | L7: 41 | M7: 363
A8: 1010157 | B8: Rosetta Primary School | C8: 27 | D8: 0 | E8: 0 | F8: 40 | G8: 34 | H8: 54 | I8: 38 | J8: 36 | K8: 42 | L8: 39 | M8: 310
A9: 1010205 | B9: Forth River Primary School, Belfast | C9: 0 | D9: 0 | E9: 0 | F9: 31 | G9: 30 | H9: 30 | I9: 30 | J9: 31 | K9: 30 | L9: 30 | M9: 212
A10: 1010221 | B10: Springfield Primary School, Belfast | C10: 0 | D10: 0 | E10: 0 | F10: 26 | G10: 26 | H10: 25 | I10: 23 | J10: 24 | K10: 28 | L10: 25 | M10: 177
A11: 1010252 | B11: Strandtown Primary School, Belfast | C11: 0 | D11: 0 | E11: 0 | F11: 0 | G11: 0 | H11: 0 | I11: 249 | J11: 241 | K11: 250 | L11: 239 | M11: 979
A12: 1010255 | B12: Elmgrove Primary School, Belfast | C12: 52 | D12: 0 | E12: 0 | F12: 75 | G12: 77 | H12: 75 | I12: 72 | J12: 75 | K12: 90 | L12: 96 | M12: 612
A13: 1010266 | B13: Seaview Primary School, Belfast | C13: 52 | D13: 0 | E13: 0 | F13: 50 | G13: 49 | H13: 63 | I13: 59 | J13: 57 | K13: 62 | L13: 56 | M13: 448
A14: 1010267 | B14: Nettlefield Primary School, Belfast | C14: 52 | D14: 0 | E14: 0 | F14: 53 | G14: 49 | H14: 56 | I14: 54 | J14: 49 | K14: 52 | L14: 48 | M14: 413
A15: 1010273 | B15: Orangefield Primary School, Belfast | C15: 52 | D15: 0 | E15: 0 | F15: 58 | G15: 50 | H15: 60 | I15: 56 | J15: 62 | K15: 62 | L15: 60 | M15: 460
A16: 1010282 | B16: Carr's Glen Primary School, Belfast | C16: 0 | D16: 25 | E16: 0 | F16: 39 | G16: 29 | H16: 55 | I16: 40 | J16: 49 | K16: 52 | L16: 51 | M16: 340
... A791: 5620263 | B791: Armagh Royal Preparatory Department | C791: 0 | D791: 0 | E791: 0 | F791: 6 | G791: 2 | H791: 6 | I791: 0 | J791: 3 | K791: 4 | L791: 9 | M791: 30
A796: Source: NI school census
A798: Notes:
A799: Data is based on pupils enrolled on Census day i.e. The Friday of the first full week in October (In 2022/23 this was the 7 October 2022)
A801: 1. Includes pupils in nursery, reception and year 1 - year 7 classes where applicable.
A802: 2. Includes pupils enrolled in nursery settings that are not part of PSEP but rather are in Specialist Provision for preschool aged children (https://www.nidirect.gov.uk/articles/pre-school-education-places).
A803: Two of these settings have an additional nursery setting which is part of PSEP (4016002 Kilcooley PS Bangor, and 5011190 Tullygally PS Craigavon),
A804: while 4 have no other nursery provision (4033040 St Brigid's PS Bangor, 4036113 St Nicholas' PS Downpatrick, 5036047 St Patrick's PS Annaghmore, and 5036706 St Columban's PS Kilkeel)

Sheet Specialist Provision
A1: Data on Pupils1,2 attending primary schools in Northern Ireland 2023/24: Specialist Provison in Mainstream
A4: DE ref | B4: school name | C4: Nursery | D4: Years 1-7 (incl Reception)
A5: 1010012 | B5: Belmont Primary School, Belfast | C5: 0 | D5: 0
A6: 1010063 | B6: Currie Primary School, Belfast | C6: 0 | D6: 9
A7: 1010146 | B7: Euston Street Primary School, Belfast | C7: 0 | D7: 0
A8: 1010157 | B8: Rosetta Primary School | C8: 0 | D8: 0
A9: 1010205 | B9: Forth River Primary School, Belfast | C9: 0 | D9: 0
A10: 1010221 | B10: Springfield Primary School, Belfast | C10: 0 | D10: 0
A11: 1010252 | B11: Strandtown Primary School, Belfast | C11: 0 | D11: 0
A12: 1010255 | B12: Elmgrove Primary School, Belfast | C12: 0 | D12: 35
A13: 1010266 | B13: Seaview Primary School, Belfast | C13: 0 | D13: 8
A14: 1010267 | B14: Nettlefield Primary School, Belfast | C14: 0 | D14: 0
A15: 1010273 | B15: Orangefield Primary School, Belfast | C15: 0 | D15: 0
A16: 1010282 | B16: Carr's Glen Primary School, Belfast | C16: 0 | D16: 0
... A791: 5620263 | B791: Armagh Royal Preparatory Department | C791: 0 | D791: 0
A796: Source: NI school census
A798: Notes:
A799: Data is based on pupils enrolled on Census day i.e. The Friday of the first full week in October (In 2022/23 this was the 7 October 2022)
A801: 1. Includes pupils in nursery, reception and year 1 - year 7 classes where applicable.
A802: 2. Includes pupils enrolled in nursery settings that are not part of PSEP but rather are in Specialist Provision for preschool aged children (https://www.nidirect.gov.uk/articles/pre-school-education-places).
A803: Two of these settings have an additional nursery setting which is part of PSEP (4016002 Kilcooley PS Bangor, and 5011190 Tullygally PS Craigavon),
A804: while 4 have no other nursery provision (4033040 St Brigid's PS Bangor, 4036113 St Nicholas' PS Downpatrick, 5036047 St Patrick's PS Annaghmore, and 5036706 St Columban's PS Kilkeel)

Sheet Sex
A1: Data on Pupils1 attending primary schools in Northern Ireland 2023/24: sex data
A2: Note: Data is not available for all schools due to ASOS (see meta data)
A4: DE ref | B4: Schoolname | C4: male | D4: female | E4: total pupils
A5: 1010012 | B5: Belmont Primary School, Belfast | C5: N/A | D5: N/A | E5: 245
A6: 1010063 | B6: Currie Primary School, Belfast | C6: N/A | D6: N/A | E6: 192
A7: 1010146 | B7: Euston Street Primary School, Belfast | C7: N/A | D7: N/A | E7: 363
A8: 1010157 | B8: Rosetta Primary School | C8: N/A | D8: N/A | E8: 310
A9: 1010205 | B9: Forth River Primary School, Belfast | C9: 92 | D9: 120 | E9: 212
A10: 1010221 | B10: Springfield Primary School, Belfast | C10: 79 | D10: 98 | E10: 177
A11: 1010252 | B11: Strandtown Primary School, Belfast | C11: N/A | D11: N/A | E11: 979
A12: 1010255 | B12: Elmgrove Primary School, Belfast | C12: N/A | D12: N/A | E12: 612
A13: 1010266 | B13: Seaview Primary School, Belfast | C13: 216 | D13: 232 | E13: 448
A14: 1010267 | B14: Nettlefield Primary School, Belfast | C14: N/A | D14: N/A | E14: 413
A15: 1010273 | B15: Orangefield Primary School, Belfast | C15: N/A | D15: N/A | E15: 460
A16: 1010282 | B16: Carr's Glen Primary School, Belfast | C16: 174 | D16: 166 | E16: 340
A17: 1010301 | B17: Taughmonagh Primary School, Belfast | C17: 150 | D17: 114 | E17: 264
A18: 1010304 | B18: Greenwood Primary School, Belfast | C18: 134 | D18: 160 | E18: 294
A19: 1010307 | B19: Springhill Primary School, Belfast | C19: 95 | D19: 100 | E19: 195
A20: 1010323 | B20: Edenbrooke Primary School, Belfast | C20: N/A | D20: N/A | E20: 367
A21: 1010324 | B21: Stranmillis Primary School, Belfast | C21: N/A | D21: N/A | E21: 466
A22: 1010325 | B22: Ligoniel Primary School, Belfast | C22: 106 | D22: 91 | E22: 197
A23: 1010806 | B23: Finaghy Primary School, Belfast | C23: N/A | D23: N/A | E23: 383
A24: 1010831 | B24: Cavehill Primary School, Belfast | C24: 198 | D24: 204 | E24: 402
A25: 1013018 | B25: Knocknagoney Primary School, Belfast | C25: 127 | D25: 122 | E25: 249
A26: 1016059 | B26: Black Mountain Primary School, Belfast | C26: N/A | D26: N/A | E26: 182
A27: 1016060 | B27: Donegall Road Primary School, Belfast | C27: 110 | D27: 99 | E27: 209
A28: 1016076 | B28: Ballysillan Primary School | C28: N/A | D28: N/A | E28: 223
A29: 1016205 | B29: Fane Street Primary School, Belfast | C29: N/A | D29: N/A | E29: 309
A30: 1016207 | B30: Blythefield Primary School, Belfast | C30: 85 | D30: 107 | E30: 192
A31: 1016242 | B31: Dundela Infants Primary School, Belfast | C31: N/A | D31: N/A | E31: 282
A32: 1016485 | B32: Glenwood Primary School, Belfast | C32: N/A | D32: N/A | E32: 508
A33: 1016498 | B33: Malvern Primary School, Belfast | C33: 94 | D33: 70 | E33: 164
A34: 1016499 | B34: Botanic Primary School, Belfast | C34: N/A | D34: N/A | E34: 210
A35: 1016532 | B35: Wheatfield Primary School, Belfast | C35: N/A | D35: N/A | E35: 176
A36: 1016537 | B36: Lowwood Primary School, Belfast | C36: 139 | D36: 104 | E36: 243
A37: 1016604 | B37: Harmony Primary School, Belfast | C37: 114 | D37: 156 | E37: 270
A38: 1016647 | B38: Bunscoil Mhic Reachtain, Belfast | C38: 23 | D38: 27 | E38: 50
A39: 1016655 | B39: Victoria Park Primary School | C39: N/A | D39: N/A | E39: 373
A40: 1030194 | B40: Holy Cross Boys' Primary School, Belfast | C40: 397 | D40: 0 | E40: 397
A41: 1030313 | B41: Our Lady of Lourdes Primary School, Belfast | C41: N/A | D41: N/A | E41: 623
...

Sheet Free School Meals
A1: Data on Pupils attending primary schools in Northern Ireland 2023/24: free school meal entitlement (fsme)1
A3: DE ref | B3: School name | C3: total enrolment | D3: fsme | E3: % fsme
A4: 1010012 | B4: =_xlfn.XLOOKUP(A4,'reference data'!A:A,'reference data'!B:B) -> Belmont Primary School, Belfast | C4: 245 | D4: 17 | E4: 0.069387755
A5: 1010063 | B5: =_xlfn.XLOOKUP(A5,'reference data'!A:A,'reference data'!B:B) -> Currie Primary School, Belfast | C5: 192 | D5: 124 | E5: 0.64583333
A6: 1010146 | B6: =_xlfn.XLOOKUP(A6,'reference data'!A:A,'reference data'!B:B) -> Euston Street Primary School, Belfast | C6: 363 | D6: 190 | E6: 0.52341598
A7: 1010157 | B7: =_xlfn.XLOOKUP(A7,'reference data'!A:A,'reference data'!B:B) -> Rosetta Primary School | C7: 310 | D7: 78 | E7: 0.2516129
A8: 1010205 | B8: =_xlfn.XLOOKUP(A8,'reference data'!A:A,'reference data'!B:B) -> Forth River Primary School, Belfast | C8: 212 | D8: 109 | E8: 0.51415094
A9: 1010221 | B9: =_xlfn.XLOOKUP(A9,'reference data'!A:A,'reference data'!B:B) -> Springfield Primary School, Belfast | C9: 177 | D9: 89 | E9: 0.50282486
A10: 1010252 | B10: =_xlfn.XLOOKUP(A10,'reference data'!A:A,'reference data'!B:B) -> Strandtown Primary School, Belfast | C10: 979 | D10: 145 | E10: 0.14811032
A11: 1010255 | B11: =_xlfn.XLOOKUP(A11,'reference data'!A:A,'reference data'!B:B) -> Elmgrove Primary School, Belfast | C11: 612 | D11: 390 | E11: 0.6372549
A12: 1010266 | B12: =_xlfn.XLOOKUP(A12,'reference data'!A:A,'reference data'!B:B) -> Seaview Primary School, Belfast | C12: 448 | D12: 207 | E12: 0.46205357
A13: 1010267 | B13: =_xlfn.XLOOKUP(A13,'reference data'!A:A,'reference data'!B:B) -> Nettlefield Primary School, Belfast | C13: 413 | D13: 259 | E13: 0.62711864
A14: 1010273 | B14: =_xlfn.XLOOKUP(A14,'reference data'!A:A,'reference data'!B:B) -> Orangefield Primary School, Belfast | C14: 460 | D14: 106 | E14: 0.23043478
A15: 1010282 | B15: =_xlfn.XLOOKUP(A15,'reference data'!A:A,'reference data'!B:B) -> Carr's Glen Primary School, Belfast | C15: 340 | D15: 151 | E15: 0.44411765
... A80: 1066580 | B80: =_xlfn.XLOOKUP(A80,'reference data'!A:A,'reference data'!B:B) -> Cranmore Integrated Primary School, Belfast | C80: 233 | D80: 89 | E80: 0.38197425
A81: 1620020 | B81: =_xlfn.XLOOKUP(A81,'reference data'!A:A,'reference data'!B:B) -> Campbell College Junior School, Belfast | C81: 203 | D81: * | E81: *
A82: 1620022 | B82: =_xlfn.XLOOKUP(A82,'reference data'!A:A,'reference data'!B:B) -> Fullerton House Preparatory School, Belfast | C82: 142 | D82: * | E82: *
A83: 1620023 | B83: =_xlfn.XLOOKUP(A83,'reference data'!A:A,'reference data'!B:B) -> Downey House Preparatory School | C83: 49 | D83: 0 | E83: 0
A84: 1620027 | B84: =_xlfn.XLOOKUP(A84,'reference data'!A:A,'reference data'!B:B) -> Inchmarlo | C84: 110 | D84: * | E84: *
A85: 1620028 | B85: =_xlfn.XLOOKUP(A85,'reference data'!A:A,'reference data'!B:B) -> Ben Madigan Preparatory School | C85: 104 | D85: * | E85: *
A86: 1620089 | B86: =_xlfn.XLOOKUP(A86,'reference data'!A:A,'reference data'!B:B) -> Strathearn Preparatory School, Belfast | C86: 131 | D86: * | E86: *
A87: 1620264 | B87: =_xlfn.XLOOKUP(A87,'reference data'!A:A,'reference data'!B:B) -> Victoria College Prep Department, Belfast | C87: 136 | D87: 0 | E87: 0
A88: 2010380 | B88: =_xlfn.XLOOKUP(A88,'reference data'!A:A,'reference data'!B:B) -> Londonderry Model Primary School | C88: 281 | D88: 91 | E88: 0.32384342
A89: 2010382 | B89: =_xlfn.XLOOKUP(A89,'reference data'!A:A,'reference data'!B:B) -> Ebrington Primary School | C89: 480 | D89: 146 | E89: 0.30416667
A90: 2011787 | B90: =_xlfn.XLOOKUP(A90,'reference data'!A:A,'reference data'!B:B) -> Kesh Primary School | C90: 244 | D90: 48 | E90: 0.19672131
A91: 2011789 | B91: =_xlfn.XLOOKUP(A91,'reference data'!A:A,'reference data'!B:B) -> Moat Primary School, Lisnaskea | C91: 135 | D91: 22 | E91: 0.16296296
A92: 2011860 | B92: =_xlfn.XLOOKUP(A92,'reference data'!A:A,'reference data'!B:B) -> Belleek No 2 Primary School | C92: 32 | D92: 5 | E92: 0.15625
A93: 2011873 | B93: =_xlfn.XLOOKUP(A93,'reference data'!A:A,'reference data'!B:B) -> Aghadrumsee Primary School, Roslea | C93: 31 | D93: 9 | E93: 0.29032258
A94: 2011879 | B94: =_xlfn.XLOOKUP(A94,'reference data'!A:A,'reference data'!B:B) -> Newtownbutler Primary School | C94: 30 | D94: 12 | E94: 0.4
A95: 2011881 | B95: =_xlfn.XLOOKUP(A95,'reference data'!A:A,'reference data'!B:B) -> Florencecourt Primary School | C95: 140 | D95: 25 | E95: 0.17857143
A96: 2011893 | B96: =_xlfn.XLOOKUP(A96,'reference data'!A:A,'reference data'!B:B) -> Ballinamallard Primary School | C96: 153 | D96: 39 | E96: 0.25490196
A97: 2011894 | B97: =_xlfn.XLOOKUP(A97,'reference data'!A:A,'reference data'!B:B) -> Brookeborough Primary School | C97: 64 | D97: 18 | E97: 0.28125
A98: 2011899 | B98: =_xlfn.XLOOKUP(A98,'reference data'!A:A,'reference data'!B:B) -> Derrygonnelly Primary School | C98: 57 | D98: 14 | E98: 0.24561404
... A109: 2012660 | B109: =_xlfn.XLOOKUP(A109,'reference data'!A:A,'reference data'!B:B) -> Denamona Primary School, Fintona | C109: 78 | D109: 18 | E109: 0.23076923
A110: 2012669 | B110: =_xlfn.XLOOKUP(A110,'reference data'!A:A,'reference data'!B:B) -> Queen Elizabeth II Primary School, Kilskeery | C110: 38 | D110: * | E110: *
A111: 2012671 | B111: =_xlfn.XLOOKUP(A111,'reference data'!A:A,'reference data'!B:B) -> Langfield Primary School, Drumquin | C111: 18 | D111: 9 | E111: 0.5
A112: 2012691 | B112: =_xlfn.XLOOKUP(A112,'reference data'!A:A,'reference data'!B:B) -> Omagh County Primary School | C112: 376 | D112: 85 | E112: 0.22606383
A113: 2012707 | B113: =_xlfn.XLOOKUP(A113,'reference data'!A:A,'reference data'!B:B) -> Dromore Primary School, Tyrone | C113: 38 | D113: 11 | E113: 0.28947368
A114: 2012708 | B114: =_xlfn.XLOOKUP(A114,'reference data'!A:A,'reference data'!B:B) -> Strabane Primary School | C114: 272 | D114: 92 | E114: 0.33823529
A115: 2012711 | B115: =_xlfn.XLOOKUP(A115,'reference data'!A:A,'reference data'!B:B) -> Donemana Primary School, Strabane | C115: 101 | D115: 26 | E115: 0.25742574
...

Sheet SEN
A1: Data on Pupils1 attending primary schools in Northern Ireland 2023/24: SEN data
A3: DE ref | B3: School name | C3: Pupils with statement of Special Educational Needs (at Stage 3 on Code of practice) | D3: Pupils at Stage 1 - 2 Special Educational Needs Code of Practice | E3: Total pupils with Special Educational needs (Stage 1 - 3 on code of practice)
A4: 1010012 | B4: Belmont Primary School, Belfast | C4: 6 | D4: 15 | E4: 21
A5: 1010063 | B5: Currie Primary School, Belfast | C5: 26 | D5: 83 | E5: 109
A6: 1010146 | B6: Euston Street Primary School, Belfast | C6: 8 | D6: 83 | E6: 91
A7: 1010157 | B7: Rosetta Primary School | C7: 13 | D7: 48 | E7: 61
A8: 1010205 | B8: Forth River Primary School, Belfast | C8: 7 | D8: 42 | E8: 49
A9: 1010221 | B9: Springfield Primary School, Belfast | C9: 6 | D9: 24 | E9: 30
A10: 1010252 | B10: Strandtown Primary School, Belfast | C10: 26 | D10: 106 | E10: 132
A11: 1010255 | B11: Elmgrove Primary School, Belfast | C11: 59 | D11: 239 | E11: 298
A12: 1010266 | B12: Seaview Primary School, Belfast | C12: 22 | D12: 83 | E12: 105
A13: 1010267 | B13: Nettlefield Primary School, Belfast | C13: 14 | D13: 60 | E13: 74
A14: 1010273 | B14: Orangefield Primary School, Belfast | C14: 16 | D14: 54 | E14: 70
A15: 1010282 | B15: Carr's Glen Primary School, Belfast | C15: 11 | D15: 49 | E15: 60
A16: 1010301 | B16: Taughmonagh Primary School, Belfast | C16: 60 | D16: 41 | E16: 101
A17: 1010304 | B17: Greenwood Primary School, Belfast | C17: * | D17: # | E17: 18
A18: 1010307 | B18: Springhill Primary School, Belfast | C18: 7 | D18: 19 | E18: 26
A19: 1010323 | B19: Edenbrooke Primary School, Belfast | C19: 36 | D19: 74 | E19: 110
A20: 1010324 | B20: Stranmillis Primary School, Belfast | C20: 13 | D20: 12 | E20: 25
A21: 1010325 | B21: Ligoniel Primary School, Belfast | C21: 12 | D21: 36 | E21: 48
A22: 1010806 | B22: Finaghy Primary School, Belfast | C22: 11 | D22: 33 | E22: 44
A23: 1010831 | B23: Cavehill Primary School, Belfast | C23: 12 | D23: 70 | E23: 82
A24: 1013018 | B24: Knocknagoney Primary School, Belfast | C24: 14 | D24: 39 | E24: 53
A25: 1016059 | B25: Black Mountain Primary School, Belfast | C25: 12 | D25: 31 | E25: 43
A26: 1016060 | B26: Donegall Road Primary School, Belfast | C26: 11 | D26: 40 | E26: 51
A27: 1016076 | B27: Ballysillan Primary School | C27: 13 | D27: 25 | E27: 38
A28: 1016205 | B28: Fane Street Primary School, Belfast | C28: 7 | D28: 84 | E28: 91
A29: 1016207 | B29: Blythefield Primary School, Belfast | C29: 10 | D29: 79 | E29: 89
... A51: 1036246 | B51: St Joseph's Primary School, Holland Dr | C51: 11 | D51: 31 | E51: 42
A52: 1036388 | B52: St Mary's Primary School, Belfast | C52: * | D52: # | E52: 63
A53: 1036466 | B53: St Malachy's Primary School, Belfast | C53: 11 | D53: 41 | E53: 52
A54: 1036471 | B54: Sacred Heart Primary School, Belfast | C54: 18 | D54: 35 | E54: 53
A55: 1036505 | B55: St Matthew's Primary School, Belfast | C55: 19 | D55: 29 | E55: 48
A56: 1036565 | B56: St Kevin's Primary School | C56: 29 | D56: 155 | E56: 184
A57: 1036566 | B57: Holy Family Primary School, Belfast | C57: 31 | D57: 128 | E57: 159
A58: 1036576 | B58: Holy Child Primary School, Belfast | C58: 18 | D58: 55 | E58: 73
A59: 1036589 | B59: St Teresa's Primary School, Belfast | C59: 66 | D59: 73 | E59: 139
A60: 1036602 | B60: St Oliver Plunkett Primary School, Belfast | C60: 35 | D60: 135 | E60: 170
A61: 1036620 | B61: St Peter's Primary School, Belfast | C61: 16 | D61: 47 | E61: 63
A62: 1036621 | B62: St Joseph's Primary School, Slate | C62: 28 | D62: 71 | E62: 99
...

Sheet Religion
A1: Data on religious background of pupils1 attending primary schools in Northern Ireland, 2023/24
A2: Note: Data is not available for all schools due to ASOS (see meta data)
A4: DE ref | B4: School name | C4: Protestant | D4: % Protestant | E4: Catholic | F4: % Catholic | G4: Other Christian / non-Christian / no religion / unknown | H4: % Other Christian / non-Christian / no religion / unknown | I4: Enrolment
A5: 1010012 | B5: Belmont Primary School, Belfast | C5: N/A | D5: N/A | E5: N/A | F5: N/A | G5: N/A | H5: N/A | I5: 245
A6: 1010063 | B6: Currie Primary School, Belfast | C6: N/A | D6: N/A | E6: N/A | F6: N/A | G6: N/A | H6: N/A | I6: 192
A7: 1010146 | B7: Euston Street Primary School, Belfast | C7: N/A | D7: N/A | E7: N/A | F7: N/A | G7: N/A | H7: N/A | I7: 363
A8: 1010157 | B8: Rosetta Primary School | C8: N/A | D8: N/A | E8: N/A | F8: N/A | G8: N/A | H8: N/A | I8: 310
A9: 1010205 | B9: Forth River Primary School, Belfast | C9: 122 | D9: 0.5754717 | E9: * | F9: * | G9: # | H9: # | I9: 212
A10: 1010221 | B10: Springfield Primary School, Belfast | C10: 149 | D10: 0.84180791 | E10: 0 | F10: 0 | G10: 28 | H10: 0.15819209 | I10: 177
A11: 1010252 | B11: Strandtown Primary School, Belfast | C11: N/A | D11: N/A | E11: N/A | F11: N/A | G11: N/A | H11: N/A | I11: 979
A12: 1010255 | B12: Elmgrove Primary School, Belfast | C12: N/A | D12: N/A | E12: N/A | F12: N/A | G12: N/A | H12: N/A | I12: 612
A13: 1010266 | B13: Seaview Primary School, Belfast | C13: 191 | D13: 0.42633929 | E13: 23 | F13: 0.051339286 | G13: 234 | H13: 0.52232143 | I13: 448
A14: 1010267 | B14: Nettlefield Primary School, Belfast | C14: N/A | D14: N/A | E14: N/A | F14: N/A | G14: N/A | H14: N/A | I14: 413
A15: 1010273 | B15: Orangefield Primary School, Belfast | C15: N/A | D15: N/A | E15: N/A | F15: N/A | G15: N/A | H15: N/A | I15: 460
A16: 1010282 | B16: Carr's Glen Primary School, Belfast | C16: 188 | D16: 0.55294118 | E16: 8 | F16: 0.023529412 | G16: 144 | H16: 0.42352941 | I16: 340
A17: 1010301 | B17: Taughmonagh Primary School, Belfast | C17: 131 | D17: 0.49621212 | E17: 20 | F17: 0.075757576 | G17: 113 | H17: 0.4280303 | I17: 264
A18: 1010304 | B18: Greenwood Primary School, Belfast | C18: 99 | D18: 0.33673469 | E18: 14 | F18: 0.047619048 | G18: 181 | H18: 0.61564626 | I18: 294
A19: 1010307 | B19: Springhill Primary School, Belfast | C19: 110 | D19: 0.56410256 | E19: 0 | F19: 0 | G19: 85 | H19: 0.43589744 | I19: 195
A20: 1010323 | B20: Edenbrooke Primary School, Belfast | C20: N/A | D20: N/A | E20: N/A | F20: N/A | G20: N/A | H20: N/A | I20: 367
A21: 1010324 | B21: Stranmillis Primary School, Belfast | C21: N/A | D21: N/A | E21: N/A | F21: N/A | G21: N/A | H21: N/A | I21: 466
A22: 1010325 | B22: Ligoniel Primary School, Belfast | C22: 115 | D22: 0.58375635 | E22: 9 | F22: 0.045685279 | G22: 73 | H22: 0.37055838 | I22: 197
A23: 1010806 | B23: Finaghy Primary School, Belfast | C23: N/A | D23: N/A | E23: N/A | F23: N/A | G23: N/A | H23: N/A | I23: 383
A24: 1010831 | B24: Cavehill Primary School, Belfast | C24: 196 | D24: 0.48756219 | E24: 52 | F24: 0.12935323 | G24: 154 | H24: 0.38308458 | I24: 402
A25: 1013018 | B25: Knocknagoney Primary School, Belfast | C25: 130 | D25: 0.52208835 | E25: 14 | F25: 0.0562249 | G25: 105 | H25: 0.42168675 | I25: 249
A26: 1016059 | B26: Black Mountain Primary School, Belfast | C26: N/A | D26: N/A | E26: N/A | F26: N/A | G26: N/A | H26: N/A | I26: 182
A27: 1016060 | B27: Donegall Road Primary School, Belfast | C27: # | D27: # | E27: * | F27: * | G27: 120 | H27: 0.57416268 | I27: 209
A28: 1016076 | B28: Ballysillan Primary School | C28: N/A | D28: N/A | E28: N/A | F28: N/A | G28: N/A | H28: N/A | I28: 223
A29: 1016205 | B29: Fane Street Primary School, Belfast | C29: N/A | D29: N/A | E29: N/A | F29: N/A | G29: N/A | H29: N/A | I29: 309
A30: 1016207 | B30: Blythefield Primary School, Belfast | C30: 151 | D30: 0.78645833 | E30: 0 | F30: 0 | G30: 41 | H30: 0.21354167 | I30: 192
A31: 1016242 | B31: Dundela Infants Primary School, Belfast | C31: N/A | D31: N/A | E31: N/A | F31: N/A | G31: N/A | H31: N/A | I31: 282
A32: 1016485 | B32: Glenwood Primary School, Belfast | C32: N/A | D32: N/A | E32: N/A | F32: N/A | G32: N/A | H32: N/A | I32: 508
A33: 1016498 | B33: Malvern Primary School, Belfast | C33: # | D33: # | E33: * | F33: * | G33: 93 | H33: 0.56707317 | I33: 164
A34: 1016499 | B34: Botanic Primary School, Belfast | C34: N/A | D34: N/A | E34: N/A | F34: N/A | G34: N/A | H34: N/A | I34: 210
A35: 1016532 | B35: Wheatfield Primary School, Belfast | C35: N/A | D35: N/A | E35: N/A | F35: N/A | G35: N/A | H35: N/A | I35: 176
A36: 1016537 | B36: Lowwood Primary School, Belfast | C36: 123 | D36: 0.50617284 | E36: 8 | F36: 0.032921811 | G36: 112 | H36: 0.46090535 | I36: 243
A37: 1016604 | B37: Harmony Primary School, Belfast | C37: 233 | D37: 0.86296296 | E37: * | F37: * | G37: # | H37: # | I37: 270
A38: 1016647 | B38: Bunscoil Mhic Reachtain, Belfast | C38: 0 | D38: 0 | E38: 47 | F38: 0.94 | G38: * | H38: * | I38: 50
A39: 1016655 | B39: Victoria Park Primary School | C39: N/A | D39: N/A | E39: N/A | F39: N/A | G39: N/A | H39: N/A | I39: 373
A40: 1030194 | B40: Holy Cross Boys' Primary School, Belfast | C40: * | D40: * | E40: # | F40: # | G40: * | H40: * | I40: 397
A41: 1030313 | B41: Our Lady of Lourdes Primary School, Belfast | C41: N/A | D41: N/A | E41: N/A | F41: N/A | G41: N/A | H41: N/A | I41: 623
...

Sheet Newcomer
A1: Data on newcomer pupils1 attending primary schools in Northern Ireland, 2023/24
A4: DE ref | B4: School name | C4: Newcomer | D4: % Newcomer | E4: Total enrolment
A5: 1010012 | B5: Belmont Primary School, Belfast | C5: * | D5: * | E5: 245
A6: 1010063 | B6: Currie Primary School, Belfast | C6: 13 | D6: 0.067708333 | E6: 192
A7: 1010146 | B7: Euston Street Primary School, Belfast | C7: 131 | D7: 0.36088154 | E7: 363
A8: 1010157 | B8: Rosetta Primary School | C8: 59 | D8: 0.19032258 | E8: 310
A9: 1010205 | B9: Forth River Primary School, Belfast | C9: * | D9: * | E9: 212
A10: 1010221 | B10: Springfield Primary School, Belfast | C10: 7 | D10: 0.039548023 | E10: 177
A11: 1010252 | B11: Strandtown Primary School, Belfast | C11: 49 | D11: 0.050051073 | E11: 979
A12: 1010255 | B12: Elmgrove Primary School, Belfast | C12: 119 | D12: 0.19444444 | E12: 612
A13: 1010266 | B13: Seaview Primary School, Belfast | C13: 120 | D13: 0.26785714 | E13: 448
A14: 1010267 | B14: Nettlefield Primary School, Belfast | C14: 167 | D14: 0.40435835 | E14: 413
A15: 1010273 | B15: Orangefield Primary School, Belfast | C15: 51 | D15: 0.11086957 | E15: 460
A16: 1010282 | B16: Carr's Glen Primary School, Belfast | C16: 27 | D16: 0.079411765 | E16: 340
A17: 1010301 | B17: Taughmonagh Primary School, Belfast | C17: 8 | D17: 0.03030303 | E17: 264
A18: 1010304 | B18: Greenwood Primary School, Belfast | C18: 11 | D18: 0.037414966 | E18: 294
A19: 1010307 | B19: Springhill Primary School, Belfast | C19: 26 | D19: 0.13333333 | E19: 195
A20: 1010323 | B20: Edenbrooke Primary School, Belfast | C20: 24 | D20: 0.065395095 | E20: 367
A21: 1010324 | B21: Stranmillis Primary School, Belfast | C21: 62 | D21: 0.13304721 | E21: 466
... A25: 1013018 | B25: Knocknagoney Primary School, Belfast | C25: 19 | D25: 0.076305221 | E25: 249
A26: 1016059 | B26: Black Mountain Primary School, Belfast | C26: * | D26: * | E26: 182
A27: 1016060 | B27: Donegall Road Primary School, Belfast | C27: 64 | D27: 0.3062201 | E27: 209
A28: 1016076 | B28: Ballysillan Primary School | C28: * | D28: * | E28: 223
A29: 1016205 | B29: Fane Street Primary School, Belfast | C29: 263 | D29: 0.85113269 | E29: 309
A30: 1016207 | B30: Blythefield Primary School, Belfast | C30: 23 | D30: 0.11979167 | E30: 192
A31: 1016242 | B31: Dundela Infants Primary School, Belfast | C31: 67 | D31: 0.23758865 | E31: 282
A32: 1016485 | B32: Glenwood Primary School, Belfast | C32: 60 | D32: 0.11811024 | E32: 508
A33: 1016498 | B33: Malvern Primary School, Belfast | C33: 62 | D33: 0.37804878 | E33: 164
A34: 1016499 | B34: Botanic Primary School, Belfast | C34: 146 | D34: 0.6952381 | E34: 210
A35: 1016532 | B35: Wheatfield Primary School, Belfast | C35: 50 | D35: 0.28409091 | E35: 176
A36: 1016537 | B36: Lowwood Primary School, Belfast | C36: 9 | D36: 0.037037037 | E36: 243
A37: 1016604 | B37: Harmony Primary School, Belfast | C37: * | D37: * | E37: 270
A38: 1016647 | B38: Bunscoil Mhic Reachtain, Belfast | C38: 0 | D38: 0 | E38: 50
A39: 1016655 | B39: Victoria Park Primary School | C39: 47 | D39: 0.12600536 | E39: 373
A40: 1030194 | B40: Holy Cross Boys' Primary School, Belfast | C40: * | D40: * | E40: 397
A41: 1030313 | B41: Our Lady of Lourdes Primary School, Belfast | C41: 11 | D41: 0.017656501 | E41: 623
A42: 1030326 | B42: Our Lady's Primary School, Belfast | C42: 6 | D42: 0.031088083 | E42: 193
A43: 1030327 | B43: Holy Rosary Primary School, Belfast | C43: 250 | D43: 0.53191489 | E43: 470
A44: 1030331 | B44: Holy Cross Girls' Primary School, Belfast | C44: * | D44: * | E44: 192
A45: 1030868 | B45: St Anne's Primary School, Belfast | C45: 69 | D45: 0.077790304 | E45: 887
...
